<?xml version="1.0"?>
<robot name="myfirst">
  <link name="base_link">
    <visual>
      <geometry>
        <box size="0.145 0.11 0.035"/>
      </geometry>
    </visual>
  </link>

  <link name="box_2_link">
    <visual>
      <!-- <origin xyz="0 0 0.035" rpy="0 0 0" /> -->
      <geometry>
        <box size="0.075 0.0375 0.035"/>
      </geometry>
    </visual>
  </link>


  <joint name="box_2_joint" type="fixed">
    <parent link="base_link"/>
    <child link="box_2_link"/>
    <origin rpy="0 0 0" xyz="0 0 0.035"/>
  </joint>


  <link name="pan_link">
    <visual>
      <!-- <origin xyz="0 0 0.1325" rpy="0 0 0" /> -->
      <geometry>
        <box size="0.0375 0.0375 0.15"/>
      </geometry>
    </visual>
  </link>

  <joint name="pan_joint" type="revolute">
    <parent link="box_2_link"/>
    <child link="pan_link"/>
    <origin rpy="0 0 0" xyz="0 0 0.0925"/>
    <axis xyz="0 0 1"/>
    <limit lower="1.83259" upper="-1.797689" effort="80.0" velocity="0.1"/>
  </joint>

  <link name="tilt_link">
    <visual>
      <geometry>
        <box size="0.06 0.08 0.035"/>
      </geometry>
    </visual>
  </link>

  <joint name="tilt_joint" type="revolute">
    <parent link="pan_link"/>
    <child link="tilt_link"/>
    <origin rpy="0 0 0" xyz="0 0 0.0925"/>
    <axis xyz="0 -1 0"/>
    <limit lower="-0.5934119" upper="3.525565" effort="80.0" velocity="0.1"/>
  </joint>

  <link name="pointer">
    <visual>
      <geometry>
        <cylinder length="0.15" radius="0.01"/>
      </geometry>
    </visual>
  </link>

  <joint name="pointer_joint" type="fixed">
    <parent link="tilt_link"/>
    <child link="pointer"/>
    <origin rpy="0 1.570796 0" xyz="0.105 0 0"/>
  </joint>

</robot>
